<mujoco model="panda">
  <compiler angle="radian" meshdir="C:/Users/kewei/.cache/robot_descriptions/mujoco_menagerie/franka_emika_panda/assets" autolimits="true" />

  <option integrator="implicitfast" />

  <default>
    <default class="panda">
      <material specular="0.5" shininess="0.25" />
      <joint armature="0.1" damping="1" axis="0 0 1" range="-2.8973 2.8973" />
      <general dyntype="none" biastype="affine" ctrlrange="-2.8973 2.8973" forcerange="-87 87" />
      <default class="finger">
        <joint axis="0 1 0" type="slide" range="0 0.04" />
      </default>

      <default class="visual">
        <geom type="mesh" contype="0" conaffinity="0" group="2" />
      </default>
      <default class="collision">
        <geom type="mesh" group="3" />
        <default class="fingertip_pad_collision_1">
          <geom type="box" size="0.0085 0.004 0.0085" pos="0 0.0055 0.0445" />
        </default>
        <default class="fingertip_pad_collision_2">
          <geom type="box" size="0.003 0.002 0.003" pos="0.0055 0.002 0.05" />
        </default>
        <default class="fingertip_pad_collision_3">
          <geom type="box" size="0.003 0.002 0.003" pos="-0.0055 0.002 0.05" />
        </default>
        <default class="fingertip_pad_collision_4">
          <geom type="box" size="0.003 0.002 0.0035" pos="0.0055 0.002 0.0395" />
        </default>
        <default class="fingertip_pad_collision_5">
          <geom type="box" size="0.003 0.002 0.0035" pos="-0.0055 0.002 0.0395" />
        </default>
      </default>
    </default>
  </default>

  <asset>
    <material class="panda" name="white" rgba="1 1 1 1" />
    <material class="panda" name="off_white" rgba="0.901961 0.921569 0.929412 1" />
    <material class="panda" name="black" rgba="0.25 0.25 0.25 1" />
    <material class="panda" name="green" rgba="0 1 0 1" />
    <material class="panda" name="light_blue" rgba="0.039216 0.541176 0.780392 1" />

    
    <mesh name="link0_c" file="link0.stl" />
    <mesh name="link1_c" file="link1.stl" />
    <mesh name="link2_c" file="link2.stl" />
    <mesh name="link3_c" file="link3.stl" />
    <mesh name="link4_c" file="link4.stl" />
    <mesh name="link5_c0" file="link5_collision_0.obj" />
    <mesh name="link5_c1" file="link5_collision_1.obj" />
    <mesh name="link5_c2" file="link5_collision_2.obj" />
    <mesh name="link6_c" file="link6.stl" />
    <mesh name="link7_c" file="link7.stl" />
    <mesh name="hand_c" file="hand.stl" />

    
    <mesh file="link0_0.obj" />
    <mesh file="link0_1.obj" />
    <mesh file="link0_2.obj" />
    <mesh file="link0_3.obj" />
    <mesh file="link0_4.obj" />
    <mesh file="link0_5.obj" />
    <mesh file="link0_7.obj" />
    <mesh file="link0_8.obj" />
    <mesh file="link0_9.obj" />
    <mesh file="link0_10.obj" />
    <mesh file="link0_11.obj" />
    <mesh file="link1.obj" />
    <mesh file="link2.obj" />
    <mesh file="link3_0.obj" />
    <mesh file="link3_1.obj" />
    <mesh file="link3_2.obj" />
    <mesh file="link3_3.obj" />
    <mesh file="link4_0.obj" />
    <mesh file="link4_1.obj" />
    <mesh file="link4_2.obj" />
    <mesh file="link4_3.obj" />
    <mesh file="link5_0.obj" />
    <mesh file="link5_1.obj" />
    <mesh file="link5_2.obj" />
    <mesh file="link6_0.obj" />
    <mesh file="link6_1.obj" />
    <mesh file="link6_2.obj" />
    <mesh file="link6_3.obj" />
    <mesh file="link6_4.obj" />
    <mesh file="link6_5.obj" />
    <mesh file="link6_6.obj" />
    <mesh file="link6_7.obj" />
    <mesh file="link6_8.obj" />
    <mesh file="link6_9.obj" />
    <mesh file="link6_10.obj" />
    <mesh file="link6_11.obj" />
    <mesh file="link6_12.obj" />
    <mesh file="link6_13.obj" />
    <mesh file="link6_14.obj" />
    <mesh file="link6_15.obj" />
    <mesh file="link6_16.obj" />
    <mesh file="link7_0.obj" />
    <mesh file="link7_1.obj" />
    <mesh file="link7_2.obj" />
    <mesh file="link7_3.obj" />
    <mesh file="link7_4.obj" />
    <mesh file="link7_5.obj" />
    <mesh file="link7_6.obj" />
    <mesh file="link7_7.obj" />
    <mesh file="hand_0.obj" />
    <mesh file="hand_1.obj" />
    <mesh file="hand_2.obj" />
    <mesh file="hand_3.obj" />
    <mesh file="hand_4.obj" />
    <mesh file="finger_0.obj" />
    <mesh file="finger_1.obj" />
  <texture type="skybox" builtin="gradient" rgb1="0.3 0.5 0.7" rgb2="0 0 0" width="512" height="3072" /><texture type="2d" name="groundplane" builtin="checker" mark="edge" rgb1="0.9 0.9 0.9" rgb2="0.8 0.8 0.8" markrgb="0.8 0.8 0.8" width="1000" height="1000" /><material name="groundplane" texture="groundplane" texuniform="true" texrepeat="1 1" reflectance="0.1" /><texture type="2d" name="light_wood" file="C:/Users/kewei/Documents/2025/04资料整理/03具身教程编写/ai-hardware-robotics/06-策略抓取或抓取VLA/大模型控制、VLA、VLM/04mujoco复现ACT、Pi0、SmolVLA/asset/tabletop/mesh/light_wood_v3.png" /><material name="wood_table_mat" texture="light_wood" specular="0.5" shininess="0.5" rgba="0.5 0.5 0.5 1" /><mesh file="C:/Users/kewei/Documents/2025/04资料整理/03具身教程编写/ai-hardware-robotics/06-策略抓取或抓取VLA/大模型控制、VLA、VLM/04mujoco复现ACT、Pi0、SmolVLA/asset/objaverse/mug_5/visual/model_normalized_0.obj" name="mug_5_normalized_0_vis" scale="0.12 0.12 0.12" refquat="0.7071067811865472 0.0 0.0 0.7071067811865476" /><mesh file="C:/Users/kewei/Documents/2025/04资料整理/03具身教程编写/ai-hardware-robotics/06-策略抓取或抓取VLA/大模型控制、VLA、VLM/04mujoco复现ACT、Pi0、SmolVLA/asset/objaverse/mug_5/collision/model_normalized_collision_22.obj" name="mug_5_normalized_collision_22._coll" scale="0.12 0.12 0.12" refquat="0.7071067811865472 0.0 0.0 0.7071067811865476" /><mesh file="C:/Users/kewei/Documents/2025/04资料整理/03具身教程编写/ai-hardware-robotics/06-策略抓取或抓取VLA/大模型控制、VLA、VLM/04mujoco复现ACT、Pi0、SmolVLA/asset/objaverse/mug_5/collision/model_normalized_collision_23.obj" name="mug_5_normalized_collision_23._coll" scale="0.12 0.12 0.12" refquat="0.7071067811865472 0.0 0.0 0.7071067811865476" /><mesh file="C:/Users/kewei/Documents/2025/04资料整理/03具身教程编写/ai-hardware-robotics/06-策略抓取或抓取VLA/大模型控制、VLA、VLM/04mujoco复现ACT、Pi0、SmolVLA/asset/objaverse/mug_5/collision/model_normalized_collision_21.obj" name="mug_5_normalized_collision_21._coll" scale="0.12 0.12 0.12" refquat="0.7071067811865472 0.0 0.0 0.7071067811865476" /><mesh file="C:/Users/kewei/Documents/2025/04资料整理/03具身教程编写/ai-hardware-robotics/06-策略抓取或抓取VLA/大模型控制、VLA、VLM/04mujoco复现ACT、Pi0、SmolVLA/asset/objaverse/mug_5/collision/model_normalized_collision_20.obj" name="mug_5_normalized_collision_20._coll" scale="0.12 0.12 0.12" refquat="0.7071067811865472 0.0 0.0 0.7071067811865476" /><mesh file="C:/Users/kewei/Documents/2025/04资料整理/03具身教程编写/ai-hardware-robotics/06-策略抓取或抓取VLA/大模型控制、VLA、VLM/04mujoco复现ACT、Pi0、SmolVLA/asset/objaverse/mug_5/collision/model_normalized_collision_24.obj" name="mug_5_normalized_collision_24._coll" scale="0.12 0.12 0.12" refquat="0.7071067811865472 0.0 0.0 0.7071067811865476" /><mesh file="C:/Users/kewei/Documents/2025/04资料整理/03具身教程编写/ai-hardware-robotics/06-策略抓取或抓取VLA/大模型控制、VLA、VLM/04mujoco复现ACT、Pi0、SmolVLA/asset/objaverse/mug_5/collision/model_normalized_collision_30.obj" name="mug_5_normalized_collision_30._coll" scale="0.12 0.12 0.12" refquat="0.7071067811865472 0.0 0.0 0.7071067811865476" /><mesh file="C:/Users/kewei/Documents/2025/04资料整理/03具身教程编写/ai-hardware-robotics/06-策略抓取或抓取VLA/大模型控制、VLA、VLM/04mujoco复现ACT、Pi0、SmolVLA/asset/objaverse/mug_5/collision/model_normalized_collision_18.obj" name="mug_5_normalized_collision_18._coll" scale="0.12 0.12 0.12" refquat="0.7071067811865472 0.0 0.0 0.7071067811865476" /><mesh file="C:/Users/kewei/Documents/2025/04资料整理/03具身教程编写/ai-hardware-robotics/06-策略抓取或抓取VLA/大模型控制、VLA、VLM/04mujoco复现ACT、Pi0、SmolVLA/asset/objaverse/mug_5/collision/model_normalized_collision_19.obj" name="mug_5_normalized_collision_19._coll" scale="0.12 0.12 0.12" refquat="0.7071067811865472 0.0 0.0 0.7071067811865476" /><mesh file="C:/Users/kewei/Documents/2025/04资料整理/03具身教程编写/ai-hardware-robotics/06-策略抓取或抓取VLA/大模型控制、VLA、VLM/04mujoco复现ACT、Pi0、SmolVLA/asset/objaverse/mug_5/collision/model_normalized_collision_31.obj" name="mug_5_normalized_collision_31._coll" scale="0.12 0.12 0.12" refquat="0.7071067811865472 0.0 0.0 0.7071067811865476" /><mesh file="C:/Users/kewei/Documents/2025/04资料整理/03具身教程编写/ai-hardware-robotics/06-策略抓取或抓取VLA/大模型控制、VLA、VLM/04mujoco复现ACT、Pi0、SmolVLA/asset/objaverse/mug_5/collision/model_normalized_collision_25.obj" name="mug_5_normalized_collision_25._coll" scale="0.12 0.12 0.12" refquat="0.7071067811865472 0.0 0.0 0.7071067811865476" /><mesh file="C:/Users/kewei/Documents/2025/04资料整理/03具身教程编写/ai-hardware-robotics/06-策略抓取或抓取VLA/大模型控制、VLA、VLM/04mujoco复现ACT、Pi0、SmolVLA/asset/objaverse/mug_5/collision/model_normalized_collision_27.obj" name="mug_5_normalized_collision_27._coll" scale="0.12 0.12 0.12" refquat="0.7071067811865472 0.0 0.0 0.7071067811865476" /><mesh file="C:/Users/kewei/Documents/2025/04资料整理/03具身教程编写/ai-hardware-robotics/06-策略抓取或抓取VLA/大模型控制、VLA、VLM/04mujoco复现ACT、Pi0、SmolVLA/asset/objaverse/mug_5/collision/model_normalized_collision_26.obj" name="mug_5_normalized_collision_26._coll" scale="0.12 0.12 0.12" refquat="0.7071067811865472 0.0 0.0 0.7071067811865476" /><mesh file="C:/Users/kewei/Documents/2025/04资料整理/03具身教程编写/ai-hardware-robotics/06-策略抓取或抓取VLA/大模型控制、VLA、VLM/04mujoco复现ACT、Pi0、SmolVLA/asset/objaverse/mug_5/collision/model_normalized_collision_9.obj" name="mug_5_normalized_collision_9._coll" scale="0.12 0.12 0.12" refquat="0.7071067811865472 0.0 0.0 0.7071067811865476" /><mesh file="C:/Users/kewei/Documents/2025/04资料整理/03具身教程编写/ai-hardware-robotics/06-策略抓取或抓取VLA/大模型控制、VLA、VLM/04mujoco复现ACT、Pi0、SmolVLA/asset/objaverse/mug_5/collision/model_normalized_collision_8.obj" name="mug_5_normalized_collision_8._coll" scale="0.12 0.12 0.12" refquat="0.7071067811865472 0.0 0.0 0.7071067811865476" /><mesh file="C:/Users/kewei/Documents/2025/04资料整理/03具身教程编写/ai-hardware-robotics/06-策略抓取或抓取VLA/大模型控制、VLA、VLM/04mujoco复现ACT、Pi0、SmolVLA/asset/objaverse/mug_5/collision/model_normalized_collision_6.obj" name="mug_5_normalized_collision_6._coll" scale="0.12 0.12 0.12" refquat="0.7071067811865472 0.0 0.0 0.7071067811865476" /><mesh file="C:/Users/kewei/Documents/2025/04资料整理/03具身教程编写/ai-hardware-robotics/06-策略抓取或抓取VLA/大模型控制、VLA、VLM/04mujoco复现ACT、Pi0、SmolVLA/asset/objaverse/mug_5/collision/model_normalized_collision_7.obj" name="mug_5_normalized_collision_7._coll" scale="0.12 0.12 0.12" refquat="0.7071067811865472 0.0 0.0 0.7071067811865476" /><mesh file="C:/Users/kewei/Documents/2025/04资料整理/03具身教程编写/ai-hardware-robotics/06-策略抓取或抓取VLA/大模型控制、VLA、VLM/04mujoco复现ACT、Pi0、SmolVLA/asset/objaverse/mug_5/collision/model_normalized_collision_5.obj" name="mug_5_normalized_collision_5._coll" scale="0.12 0.12 0.12" refquat="0.7071067811865472 0.0 0.0 0.7071067811865476" /><mesh file="C:/Users/kewei/Documents/2025/04资料整理/03具身教程编写/ai-hardware-robotics/06-策略抓取或抓取VLA/大模型控制、VLA、VLM/04mujoco复现ACT、Pi0、SmolVLA/asset/objaverse/mug_5/collision/model_normalized_collision_4.obj" name="mug_5_normalized_collision_4._coll" scale="0.12 0.12 0.12" refquat="0.7071067811865472 0.0 0.0 0.7071067811865476" /><mesh file="C:/Users/kewei/Documents/2025/04资料整理/03具身教程编写/ai-hardware-robotics/06-策略抓取或抓取VLA/大模型控制、VLA、VLM/04mujoco复现ACT、Pi0、SmolVLA/asset/objaverse/mug_5/collision/model_normalized_collision_0.obj" name="mug_5_normalized_collision_0._coll" scale="0.12 0.12 0.12" refquat="0.7071067811865472 0.0 0.0 0.7071067811865476" /><mesh file="C:/Users/kewei/Documents/2025/04资料整理/03具身教程编写/ai-hardware-robotics/06-策略抓取或抓取VLA/大模型控制、VLA、VLM/04mujoco复现ACT、Pi0、SmolVLA/asset/objaverse/mug_5/collision/model_normalized_collision_1.obj" name="mug_5_normalized_collision_1._coll" scale="0.12 0.12 0.12" refquat="0.7071067811865472 0.0 0.0 0.7071067811865476" /><mesh file="C:/Users/kewei/Documents/2025/04资料整理/03具身教程编写/ai-hardware-robotics/06-策略抓取或抓取VLA/大模型控制、VLA、VLM/04mujoco复现ACT、Pi0、SmolVLA/asset/objaverse/mug_5/collision/model_normalized_collision_3.obj" name="mug_5_normalized_collision_3._coll" scale="0.12 0.12 0.12" refquat="0.7071067811865472 0.0 0.0 0.7071067811865476" /><mesh file="C:/Users/kewei/Documents/2025/04资料整理/03具身教程编写/ai-hardware-robotics/06-策略抓取或抓取VLA/大模型控制、VLA、VLM/04mujoco复现ACT、Pi0、SmolVLA/asset/objaverse/mug_5/collision/model_normalized_collision_2.obj" name="mug_5_normalized_collision_2._coll" scale="0.12 0.12 0.12" refquat="0.7071067811865472 0.0 0.0 0.7071067811865476" /><mesh file="C:/Users/kewei/Documents/2025/04资料整理/03具身教程编写/ai-hardware-robotics/06-策略抓取或抓取VLA/大模型控制、VLA、VLM/04mujoco复现ACT、Pi0、SmolVLA/asset/objaverse/mug_5/collision/model_normalized_collision_17.obj" name="mug_5_normalized_collision_17._coll" scale="0.12 0.12 0.12" refquat="0.7071067811865472 0.0 0.0 0.7071067811865476" /><mesh file="C:/Users/kewei/Documents/2025/04资料整理/03具身教程编写/ai-hardware-robotics/06-策略抓取或抓取VLA/大模型控制、VLA、VLM/04mujoco复现ACT、Pi0、SmolVLA/asset/objaverse/mug_5/collision/model_normalized_collision_16.obj" name="mug_5_normalized_collision_16._coll" scale="0.12 0.12 0.12" refquat="0.7071067811865472 0.0 0.0 0.7071067811865476" /><mesh file="C:/Users/kewei/Documents/2025/04资料整理/03具身教程编写/ai-hardware-robotics/06-策略抓取或抓取VLA/大模型控制、VLA、VLM/04mujoco复现ACT、Pi0、SmolVLA/asset/objaverse/mug_5/collision/model_normalized_collision_28.obj" name="mug_5_normalized_collision_28._coll" scale="0.12 0.12 0.12" refquat="0.7071067811865472 0.0 0.0 0.7071067811865476" /><mesh file="C:/Users/kewei/Documents/2025/04资料整理/03具身教程编写/ai-hardware-robotics/06-策略抓取或抓取VLA/大模型控制、VLA、VLM/04mujoco复现ACT、Pi0、SmolVLA/asset/objaverse/mug_5/collision/model_normalized_collision_14.obj" name="mug_5_normalized_collision_14._coll" scale="0.12 0.12 0.12" refquat="0.7071067811865472 0.0 0.0 0.7071067811865476" /><mesh file="C:/Users/kewei/Documents/2025/04资料整理/03具身教程编写/ai-hardware-robotics/06-策略抓取或抓取VLA/大模型控制、VLA、VLM/04mujoco复现ACT、Pi0、SmolVLA/asset/objaverse/mug_5/collision/model_normalized_collision_15.obj" name="mug_5_normalized_collision_15._coll" scale="0.12 0.12 0.12" refquat="0.7071067811865472 0.0 0.0 0.7071067811865476" /><mesh file="C:/Users/kewei/Documents/2025/04资料整理/03具身教程编写/ai-hardware-robotics/06-策略抓取或抓取VLA/大模型控制、VLA、VLM/04mujoco复现ACT、Pi0、SmolVLA/asset/objaverse/mug_5/collision/model_normalized_collision_29.obj" name="mug_5_normalized_collision_29._coll" scale="0.12 0.12 0.12" refquat="0.7071067811865472 0.0 0.0 0.7071067811865476" /><mesh file="C:/Users/kewei/Documents/2025/04资料整理/03具身教程编写/ai-hardware-robotics/06-策略抓取或抓取VLA/大模型控制、VLA、VLM/04mujoco复现ACT、Pi0、SmolVLA/asset/objaverse/mug_5/collision/model_normalized_collision_11.obj" name="mug_5_normalized_collision_11._coll" scale="0.12 0.12 0.12" refquat="0.7071067811865472 0.0 0.0 0.7071067811865476" /><mesh file="C:/Users/kewei/Documents/2025/04资料整理/03具身教程编写/ai-hardware-robotics/06-策略抓取或抓取VLA/大模型控制、VLA、VLM/04mujoco复现ACT、Pi0、SmolVLA/asset/objaverse/mug_5/collision/model_normalized_collision_10.obj" name="mug_5_normalized_collision_10._coll" scale="0.12 0.12 0.12" refquat="0.7071067811865472 0.0 0.0 0.7071067811865476" /><mesh file="C:/Users/kewei/Documents/2025/04资料整理/03具身教程编写/ai-hardware-robotics/06-策略抓取或抓取VLA/大模型控制、VLA、VLM/04mujoco复现ACT、Pi0、SmolVLA/asset/objaverse/mug_5/collision/model_normalized_collision_12.obj" name="mug_5_normalized_collision_12._coll" scale="0.12 0.12 0.12" refquat="0.7071067811865472 0.0 0.0 0.7071067811865476" /><mesh file="C:/Users/kewei/Documents/2025/04资料整理/03具身教程编写/ai-hardware-robotics/06-策略抓取或抓取VLA/大模型控制、VLA、VLM/04mujoco复现ACT、Pi0、SmolVLA/asset/objaverse/mug_5/collision/model_normalized_collision_13.obj" name="mug_5_normalized_collision_13._coll" scale="0.12 0.12 0.12" refquat="0.7071067811865472 0.0 0.0 0.7071067811865476" /><texture type="2d" name="mug_50" file="C:/Users/kewei/Documents/2025/04资料整理/03具身教程编写/ai-hardware-robotics/06-策略抓取或抓取VLA/大模型控制、VLA、VLM/04mujoco复现ACT、Pi0、SmolVLA/asset/objaverse/mug_5/visual/image0.png" /><material name="m_mug_mug_5" texture="mug_50" specular="0.5" shininess="0.359999993" /><mesh file="C:/Users/kewei/Documents/2025/04资料整理/03具身教程编写/ai-hardware-robotics/06-策略抓取或抓取VLA/大模型控制、VLA、VLM/04mujoco复现ACT、Pi0、SmolVLA/asset/objaverse/plate_11/visual/model_normalized_0.obj" name="plate_11_normalized_0_vis" scale="0.24975 0.24975 0.24975" refquat="1.0 0.0 0.0 0.0" /><mesh file="C:/Users/kewei/Documents/2025/04资料整理/03具身教程编写/ai-hardware-robotics/06-策略抓取或抓取VLA/大模型控制、VLA、VLM/04mujoco复现ACT、Pi0、SmolVLA/asset/objaverse/plate_11/collision/model_normalized_collision_22.obj" name="plate_11_normalized_collision_22._coll" scale="0.24975 0.24975 0.24975" refquat="1.0 0.0 0.0 0.0" /><mesh file="C:/Users/kewei/Documents/2025/04资料整理/03具身教程编写/ai-hardware-robotics/06-策略抓取或抓取VLA/大模型控制、VLA、VLM/04mujoco复现ACT、Pi0、SmolVLA/asset/objaverse/plate_11/collision/model_normalized_collision_23.obj" name="plate_11_normalized_collision_23._coll" scale="0.24975 0.24975 0.24975" refquat="1.0 0.0 0.0 0.0" /><mesh file="C:/Users/kewei/Documents/2025/04资料整理/03具身教程编写/ai-hardware-robotics/06-策略抓取或抓取VLA/大模型控制、VLA、VLM/04mujoco复现ACT、Pi0、SmolVLA/asset/objaverse/plate_11/collision/model_normalized_collision_21.obj" name="plate_11_normalized_collision_21._coll" scale="0.24975 0.24975 0.24975" refquat="1.0 0.0 0.0 0.0" /><mesh file="C:/Users/kewei/Documents/2025/04资料整理/03具身教程编写/ai-hardware-robotics/06-策略抓取或抓取VLA/大模型控制、VLA、VLM/04mujoco复现ACT、Pi0、SmolVLA/asset/objaverse/plate_11/collision/model_normalized_collision_20.obj" name="plate_11_normalized_collision_20._coll" scale="0.24975 0.24975 0.24975" refquat="1.0 0.0 0.0 0.0" /><mesh file="C:/Users/kewei/Documents/2025/04资料整理/03具身教程编写/ai-hardware-robotics/06-策略抓取或抓取VLA/大模型控制、VLA、VLM/04mujoco复现ACT、Pi0、SmolVLA/asset/objaverse/plate_11/collision/model_normalized_collision_24.obj" name="plate_11_normalized_collision_24._coll" scale="0.24975 0.24975 0.24975" refquat="1.0 0.0 0.0 0.0" /><mesh file="C:/Users/kewei/Documents/2025/04资料整理/03具身教程编写/ai-hardware-robotics/06-策略抓取或抓取VLA/大模型控制、VLA、VLM/04mujoco复现ACT、Pi0、SmolVLA/asset/objaverse/plate_11/collision/model_normalized_collision_30.obj" name="plate_11_normalized_collision_30._coll" scale="0.24975 0.24975 0.24975" refquat="1.0 0.0 0.0 0.0" /><mesh file="C:/Users/kewei/Documents/2025/04资料整理/03具身教程编写/ai-hardware-robotics/06-策略抓取或抓取VLA/大模型控制、VLA、VLM/04mujoco复现ACT、Pi0、SmolVLA/asset/objaverse/plate_11/collision/model_normalized_collision_18.obj" name="plate_11_normalized_collision_18._coll" scale="0.24975 0.24975 0.24975" refquat="1.0 0.0 0.0 0.0" /><mesh file="C:/Users/kewei/Documents/2025/04资料整理/03具身教程编写/ai-hardware-robotics/06-策略抓取或抓取VLA/大模型控制、VLA、VLM/04mujoco复现ACT、Pi0、SmolVLA/asset/objaverse/plate_11/collision/model_normalized_collision_19.obj" name="plate_11_normalized_collision_19._coll" scale="0.24975 0.24975 0.24975" refquat="1.0 0.0 0.0 0.0" /><mesh file="C:/Users/kewei/Documents/2025/04资料整理/03具身教程编写/ai-hardware-robotics/06-策略抓取或抓取VLA/大模型控制、VLA、VLM/04mujoco复现ACT、Pi0、SmolVLA/asset/objaverse/plate_11/collision/model_normalized_collision_31.obj" name="plate_11_normalized_collision_31._coll" scale="0.24975 0.24975 0.24975" refquat="1.0 0.0 0.0 0.0" /><mesh file="C:/Users/kewei/Documents/2025/04资料整理/03具身教程编写/ai-hardware-robotics/06-策略抓取或抓取VLA/大模型控制、VLA、VLM/04mujoco复现ACT、Pi0、SmolVLA/asset/objaverse/plate_11/collision/model_normalized_collision_25.obj" name="plate_11_normalized_collision_25._coll" scale="0.24975 0.24975 0.24975" refquat="1.0 0.0 0.0 0.0" /><mesh file="C:/Users/kewei/Documents/2025/04资料整理/03具身教程编写/ai-hardware-robotics/06-策略抓取或抓取VLA/大模型控制、VLA、VLM/04mujoco复现ACT、Pi0、SmolVLA/asset/objaverse/plate_11/collision/model_normalized_collision_27.obj" name="plate_11_normalized_collision_27._coll" scale="0.24975 0.24975 0.24975" refquat="1.0 0.0 0.0 0.0" /><mesh file="C:/Users/kewei/Documents/2025/04资料整理/03具身教程编写/ai-hardware-robotics/06-策略抓取或抓取VLA/大模型控制、VLA、VLM/04mujoco复现ACT、Pi0、SmolVLA/asset/objaverse/plate_11/collision/model_normalized_collision_26.obj" name="plate_11_normalized_collision_26._coll" scale="0.24975 0.24975 0.24975" refquat="1.0 0.0 0.0 0.0" /><mesh file="C:/Users/kewei/Documents/2025/04资料整理/03具身教程编写/ai-hardware-robotics/06-策略抓取或抓取VLA/大模型控制、VLA、VLM/04mujoco复现ACT、Pi0、SmolVLA/asset/objaverse/plate_11/collision/model_normalized_collision_9.obj" name="plate_11_normalized_collision_9._coll" scale="0.24975 0.24975 0.24975" refquat="1.0 0.0 0.0 0.0" /><mesh file="C:/Users/kewei/Documents/2025/04资料整理/03具身教程编写/ai-hardware-robotics/06-策略抓取或抓取VLA/大模型控制、VLA、VLM/04mujoco复现ACT、Pi0、SmolVLA/asset/objaverse/plate_11/collision/model_normalized_collision_8.obj" name="plate_11_normalized_collision_8._coll" scale="0.24975 0.24975 0.24975" refquat="1.0 0.0 0.0 0.0" /><mesh file="C:/Users/kewei/Documents/2025/04资料整理/03具身教程编写/ai-hardware-robotics/06-策略抓取或抓取VLA/大模型控制、VLA、VLM/04mujoco复现ACT、Pi0、SmolVLA/asset/objaverse/plate_11/collision/model_normalized_collision_6.obj" name="plate_11_normalized_collision_6._coll" scale="0.24975 0.24975 0.24975" refquat="1.0 0.0 0.0 0.0" /><mesh file="C:/Users/kewei/Documents/2025/04资料整理/03具身教程编写/ai-hardware-robotics/06-策略抓取或抓取VLA/大模型控制、VLA、VLM/04mujoco复现ACT、Pi0、SmolVLA/asset/objaverse/plate_11/collision/model_normalized_collision_7.obj" name="plate_11_normalized_collision_7._coll" scale="0.24975 0.24975 0.24975" refquat="1.0 0.0 0.0 0.0" /><mesh file="C:/Users/kewei/Documents/2025/04资料整理/03具身教程编写/ai-hardware-robotics/06-策略抓取或抓取VLA/大模型控制、VLA、VLM/04mujoco复现ACT、Pi0、SmolVLA/asset/objaverse/plate_11/collision/model_normalized_collision_5.obj" name="plate_11_normalized_collision_5._coll" scale="0.24975 0.24975 0.24975" refquat="1.0 0.0 0.0 0.0" /><mesh file="C:/Users/kewei/Documents/2025/04资料整理/03具身教程编写/ai-hardware-robotics/06-策略抓取或抓取VLA/大模型控制、VLA、VLM/04mujoco复现ACT、Pi0、SmolVLA/asset/objaverse/plate_11/collision/model_normalized_collision_4.obj" name="plate_11_normalized_collision_4._coll" scale="0.24975 0.24975 0.24975" refquat="1.0 0.0 0.0 0.0" /><mesh file="C:/Users/kewei/Documents/2025/04资料整理/03具身教程编写/ai-hardware-robotics/06-策略抓取或抓取VLA/大模型控制、VLA、VLM/04mujoco复现ACT、Pi0、SmolVLA/asset/objaverse/plate_11/collision/model_normalized_collision_0.obj" name="plate_11_normalized_collision_0._coll" scale="0.24975 0.24975 0.24975" refquat="1.0 0.0 0.0 0.0" /><mesh file="C:/Users/kewei/Documents/2025/04资料整理/03具身教程编写/ai-hardware-robotics/06-策略抓取或抓取VLA/大模型控制、VLA、VLM/04mujoco复现ACT、Pi0、SmolVLA/asset/objaverse/plate_11/collision/model_normalized_collision_1.obj" name="plate_11_normalized_collision_1._coll" scale="0.24975 0.24975 0.24975" refquat="1.0 0.0 0.0 0.0" /><mesh file="C:/Users/kewei/Documents/2025/04资料整理/03具身教程编写/ai-hardware-robotics/06-策略抓取或抓取VLA/大模型控制、VLA、VLM/04mujoco复现ACT、Pi0、SmolVLA/asset/objaverse/plate_11/collision/model_normalized_collision_3.obj" name="plate_11_normalized_collision_3._coll" scale="0.24975 0.24975 0.24975" refquat="1.0 0.0 0.0 0.0" /><mesh file="C:/Users/kewei/Documents/2025/04资料整理/03具身教程编写/ai-hardware-robotics/06-策略抓取或抓取VLA/大模型控制、VLA、VLM/04mujoco复现ACT、Pi0、SmolVLA/asset/objaverse/plate_11/collision/model_normalized_collision_2.obj" name="plate_11_normalized_collision_2._coll" scale="0.24975 0.24975 0.24975" refquat="1.0 0.0 0.0 0.0" /><mesh file="C:/Users/kewei/Documents/2025/04资料整理/03具身教程编写/ai-hardware-robotics/06-策略抓取或抓取VLA/大模型控制、VLA、VLM/04mujoco复现ACT、Pi0、SmolVLA/asset/objaverse/plate_11/collision/model_normalized_collision_17.obj" name="plate_11_normalized_collision_17._coll" scale="0.24975 0.24975 0.24975" refquat="1.0 0.0 0.0 0.0" /><mesh file="C:/Users/kewei/Documents/2025/04资料整理/03具身教程编写/ai-hardware-robotics/06-策略抓取或抓取VLA/大模型控制、VLA、VLM/04mujoco复现ACT、Pi0、SmolVLA/asset/objaverse/plate_11/collision/model_normalized_collision_16.obj" name="plate_11_normalized_collision_16._coll" scale="0.24975 0.24975 0.24975" refquat="1.0 0.0 0.0 0.0" /><mesh file="C:/Users/kewei/Documents/2025/04资料整理/03具身教程编写/ai-hardware-robotics/06-策略抓取或抓取VLA/大模型控制、VLA、VLM/04mujoco复现ACT、Pi0、SmolVLA/asset/objaverse/plate_11/collision/model_normalized_collision_28.obj" name="plate_11_normalized_collision_28._coll" scale="0.24975 0.24975 0.24975" refquat="1.0 0.0 0.0 0.0" /><mesh file="C:/Users/kewei/Documents/2025/04资料整理/03具身教程编写/ai-hardware-robotics/06-策略抓取或抓取VLA/大模型控制、VLA、VLM/04mujoco复现ACT、Pi0、SmolVLA/asset/objaverse/plate_11/collision/model_normalized_collision_14.obj" name="plate_11_normalized_collision_14._coll" scale="0.24975 0.24975 0.24975" refquat="1.0 0.0 0.0 0.0" /><mesh file="C:/Users/kewei/Documents/2025/04资料整理/03具身教程编写/ai-hardware-robotics/06-策略抓取或抓取VLA/大模型控制、VLA、VLM/04mujoco复现ACT、Pi0、SmolVLA/asset/objaverse/plate_11/collision/model_normalized_collision_15.obj" name="plate_11_normalized_collision_15._coll" scale="0.24975 0.24975 0.24975" refquat="1.0 0.0 0.0 0.0" /><mesh file="C:/Users/kewei/Documents/2025/04资料整理/03具身教程编写/ai-hardware-robotics/06-策略抓取或抓取VLA/大模型控制、VLA、VLM/04mujoco复现ACT、Pi0、SmolVLA/asset/objaverse/plate_11/collision/model_normalized_collision_29.obj" name="plate_11_normalized_collision_29._coll" scale="0.24975 0.24975 0.24975" refquat="1.0 0.0 0.0 0.0" /><mesh file="C:/Users/kewei/Documents/2025/04资料整理/03具身教程编写/ai-hardware-robotics/06-策略抓取或抓取VLA/大模型控制、VLA、VLM/04mujoco复现ACT、Pi0、SmolVLA/asset/objaverse/plate_11/collision/model_normalized_collision_11.obj" name="plate_11_normalized_collision_11._coll" scale="0.24975 0.24975 0.24975" refquat="1.0 0.0 0.0 0.0" /><mesh file="C:/Users/kewei/Documents/2025/04资料整理/03具身教程编写/ai-hardware-robotics/06-策略抓取或抓取VLA/大模型控制、VLA、VLM/04mujoco复现ACT、Pi0、SmolVLA/asset/objaverse/plate_11/collision/model_normalized_collision_10.obj" name="plate_11_normalized_collision_10._coll" scale="0.24975 0.24975 0.24975" refquat="1.0 0.0 0.0 0.0" /><mesh file="C:/Users/kewei/Documents/2025/04资料整理/03具身教程编写/ai-hardware-robotics/06-策略抓取或抓取VLA/大模型控制、VLA、VLM/04mujoco复现ACT、Pi0、SmolVLA/asset/objaverse/plate_11/collision/model_normalized_collision_12.obj" name="plate_11_normalized_collision_12._coll" scale="0.24975 0.24975 0.24975" refquat="1.0 0.0 0.0 0.0" /><mesh file="C:/Users/kewei/Documents/2025/04资料整理/03具身教程编写/ai-hardware-robotics/06-策略抓取或抓取VLA/大模型控制、VLA、VLM/04mujoco复现ACT、Pi0、SmolVLA/asset/objaverse/plate_11/collision/model_normalized_collision_13.obj" name="plate_11_normalized_collision_13._coll" scale="0.24975 0.24975 0.24975" refquat="1.0 0.0 0.0 0.0" /><material name="Material.387_plate_11" specular="0.5" shininess="0.359999993" rgba="0.800000 0.800000 0.800000 1.0" /></asset>

  <worldbody>
    <light name="top" pos="0 0 2" mode="trackcom" />
    <body name="link0" childclass="panda" pos="0 0 0.82">
      <inertial mass="0.629769" pos="-0.041018 -0.00014 0.049974" fullinertia="0.00315 0.00388 0.004285 8.2904e-7 0.00015 8.2299e-6" />
      <geom mesh="link0_0" material="off_white" class="visual" />
      <geom mesh="link0_1" material="black" class="visual" />
      <geom mesh="link0_2" material="off_white" class="visual" />
      <geom mesh="link0_3" material="black" class="visual" />
      <geom mesh="link0_4" material="off_white" class="visual" />
      <geom mesh="link0_5" material="black" class="visual" />
      <geom mesh="link0_7" material="white" class="visual" />
      <geom mesh="link0_8" material="white" class="visual" />
      <geom mesh="link0_9" material="black" class="visual" />
      <geom mesh="link0_10" material="off_white" class="visual" />
      <geom mesh="link0_11" material="white" class="visual" />
      <geom mesh="link0_c" class="collision" />
      <body name="link1" pos="0 0 0.333">
        <inertial mass="4.970684" pos="0.003875 0.002081 -0.04762" fullinertia="0.70337 0.70661 0.0091170 -0.00013900 0.0067720 0.019169" />
        <joint name="joint1" />
        <geom material="white" mesh="link1" class="visual" />
        <geom mesh="link1_c" class="collision" />
        <body name="link2" quat="1 -1 0 0">
          <inertial mass="0.646926" pos="-0.003141 -0.02872 0.003495" fullinertia="0.0079620 2.8110e-2 2.5995e-2 -3.925e-3 1.0254e-2 7.04e-4" />
          <joint name="joint2" range="-1.7628 1.7628" />
          <geom material="white" mesh="link2" class="visual" />
          <geom mesh="link2_c" class="collision" />
          <body name="link3" pos="0 -0.316 0" quat="1 1 0 0">
            <joint name="joint3" />
            <inertial mass="3.228604" pos="2.7518e-2 3.9252e-2 -6.6502e-2" fullinertia="3.7242e-2 3.6155e-2 1.083e-2 -4.761e-3 -1.1396e-2 -1.2805e-2" />
            <geom mesh="link3_0" material="white" class="visual" />
            <geom mesh="link3_1" material="white" class="visual" />
            <geom mesh="link3_2" material="white" class="visual" />
            <geom mesh="link3_3" material="black" class="visual" />
            <geom mesh="link3_c" class="collision" />
            <body name="link4" pos="0.0825 0 0" quat="1 1 0 0">
              <inertial mass="3.587895" pos="-5.317e-2 1.04419e-1 2.7454e-2" fullinertia="2.5853e-2 1.9552e-2 2.8323e-2 7.796e-3 -1.332e-3 8.641e-3" />
              <joint name="joint4" range="-3.0718 -0.0698" />
              <geom mesh="link4_0" material="white" class="visual" />
              <geom mesh="link4_1" material="white" class="visual" />
              <geom mesh="link4_2" material="black" class="visual" />
              <geom mesh="link4_3" material="white" class="visual" />
              <geom mesh="link4_c" class="collision" />
              <body name="link5" pos="-0.0825 0.384 0" quat="1 -1 0 0">
                <inertial mass="1.225946" pos="-1.1953e-2 4.1065e-2 -3.8437e-2" fullinertia="3.5549e-2 2.9474e-2 8.627e-3 -2.117e-3 -4.037e-3 2.29e-4" />
                <joint name="joint5" />
                <geom mesh="link5_0" material="black" class="visual" />
                <geom mesh="link5_1" material="white" class="visual" />
                <geom mesh="link5_2" material="white" class="visual" />
                <geom mesh="link5_c0" class="collision" />
                <geom mesh="link5_c1" class="collision" />
                <geom mesh="link5_c2" class="collision" />
                <body name="link6" quat="1 1 0 0">
                  <inertial mass="1.666555" pos="6.0149e-2 -1.4117e-2 -1.0517e-2" fullinertia="1.964e-3 4.354e-3 5.433e-3 1.09e-4 -1.158e-3 3.41e-4" />
                  <joint name="joint6" range="-0.0175 3.7525" />
                  <geom mesh="link6_0" material="off_white" class="visual" />
                  <geom mesh="link6_1" material="white" class="visual" />
                  <geom mesh="link6_2" material="black" class="visual" />
                  <geom mesh="link6_3" material="white" class="visual" />
                  <geom mesh="link6_4" material="white" class="visual" />
                  <geom mesh="link6_5" material="white" class="visual" />
                  <geom mesh="link6_6" material="white" class="visual" />
                  <geom mesh="link6_7" material="light_blue" class="visual" />
                  <geom mesh="link6_8" material="light_blue" class="visual" />
                  <geom mesh="link6_9" material="black" class="visual" />
                  <geom mesh="link6_10" material="black" class="visual" />
                  <geom mesh="link6_11" material="white" class="visual" />
                  <geom mesh="link6_12" material="green" class="visual" />
                  <geom mesh="link6_13" material="white" class="visual" />
                  <geom mesh="link6_14" material="black" class="visual" />
                  <geom mesh="link6_15" material="black" class="visual" />
                  <geom mesh="link6_16" material="white" class="visual" />
                  <geom mesh="link6_c" class="collision" />
                  <body name="link7" pos="0.088 0 0" quat="1 1 0 0">
                    <inertial mass="7.35522e-01" pos="1.0517e-2 -4.252e-3 6.1597e-2" fullinertia="1.2516e-2 1.0027e-2 4.815e-3 -4.28e-4 -1.196e-3 -7.41e-4" />
                    <joint name="joint7" />
                    <geom mesh="link7_0" material="white" class="visual" />
                    <geom mesh="link7_1" material="black" class="visual" />
                    <geom mesh="link7_2" material="black" class="visual" />
                    <geom mesh="link7_3" material="black" class="visual" />
                    <geom mesh="link7_4" material="black" class="visual" />
                    <geom mesh="link7_5" material="black" class="visual" />
                    <geom mesh="link7_6" material="black" class="visual" />
                    <geom mesh="link7_7" material="white" class="visual" />
                    <geom mesh="link7_c" class="collision" />
                    <body name="hand" pos="0 0 0.107" quat="0.9238795 0 0 -0.3826834">
                      <inertial mass="0.73" pos="-0.01 0 0.03" diaginertia="0.001 0.0025 0.0017" />
                      <geom mesh="hand_0" material="off_white" class="visual" />
                      <geom mesh="hand_1" material="black" class="visual" />
                      <geom mesh="hand_2" material="black" class="visual" />
                      <geom mesh="hand_3" material="white" class="visual" />
                      <geom mesh="hand_4" material="off_white" class="visual" />
                      <geom mesh="hand_c" class="collision" />
                      <body name="left_finger" pos="0 0 0.0584">
                        <inertial mass="0.015" pos="0 0 0" diaginertia="2.375e-6 2.375e-6 7.5e-7" />
                        <joint name="finger_joint1" class="finger" />
                        <geom mesh="finger_0" material="off_white" class="visual" />
                        <geom mesh="finger_1" material="black" class="visual" />
                        <geom mesh="finger_0" class="collision" />
                        <geom class="fingertip_pad_collision_1" />
                        <geom class="fingertip_pad_collision_2" />
                        <geom class="fingertip_pad_collision_3" />
                        <geom class="fingertip_pad_collision_4" />
                        <geom class="fingertip_pad_collision_5" />
                      </body>
                      <body name="right_finger" pos="0 0 0.0584" quat="0 0 0 1">
                        <inertial mass="0.015" pos="0 0 0" diaginertia="2.375e-6 2.375e-6 7.5e-7" />
                        <joint name="finger_joint2" class="finger" />
                        <geom mesh="finger_0" material="off_white" class="visual" />
                        <geom mesh="finger_1" material="black" class="visual" />
                        <geom mesh="finger_0" class="collision" />
                        <geom class="fingertip_pad_collision_1" />
                        <geom class="fingertip_pad_collision_2" />
                        <geom class="fingertip_pad_collision_3" />
                        <geom class="fingertip_pad_collision_4" />
                        <geom class="fingertip_pad_collision_5" />
                      </body>
                    <camera name="egocentric" pos="0.0 -0.06 0.05" xyaxes="-1 0 0 0 0 1" fovy="90" /></body>
                  </body>
                </body>
              </body>
            </body>
          </body>
        </body>
      </body>
    </body>
  <light pos="1 -1 1.5" dir="-1 1 -1" diffuse="0.5 0.5 0.5" directional="true" /><geom name="floor" group="1" size="0 0 0.05" type="plane" material="groundplane" /><body name="front_object_table" pos="0 0 0" euler="0 0 0">
            <geom name="front_object_table" size="1.0 0.7 0.4" pos="0.5 0 0.4" type="box" material="wood_table_mat" />
            <inertial pos="0 0 0" mass="1" diaginertia="0 0 0" />

           <body name="camera" pos="0.8 0.0 1.2">
                <camera name="agentview" pos="0 0 0" xyaxes="0 1 0  -0.5 0 0.707" fovy="60" />
            </body>

            <body name="camera2" pos="0.5 0.0 1.8">
                <camera name="topview" pos="0 0 0" xyaxes="0 -1 0 1 0 0" fovy="90" />
            </body>

            <body name="camera3" pos="0.3 -0.7 1.3">
                <camera name="sideview" pos="0 0 0" xyaxes="1 0 0 0 0 1" fovy="90" />
            </body>

        </body><body name="body_obj_mug_5">
      <freejoint /><body name="object_mug_5">
        <geom solimp="0.998 0.998 0.001" solref="0.001 1" density="100" friction="0.95 0.3 0.1" type="mesh" mesh="mug_5_normalized_0_vis" conaffinity="0" contype="0" group="2" material="m_mug_mug_5" />
        <geom solimp="0.998 0.998 0.001" solref="0.001 1" density="100" friction="0.95 0.3 0.1" type="mesh" mesh="mug_5_normalized_collision_22._coll" group="3" rgba="0.8 0.8 0.8 0.0" />
        <geom solimp="0.998 0.998 0.001" solref="0.001 1" density="100" friction="0.95 0.3 0.1" type="mesh" mesh="mug_5_normalized_collision_23._coll" group="3" rgba="0.8 0.8 0.8 0.0" />
        <geom solimp="0.998 0.998 0.001" solref="0.001 1" density="100" friction="0.95 0.3 0.1" type="mesh" mesh="mug_5_normalized_collision_21._coll" group="3" rgba="0.8 0.8 0.8 0.0" />
        <geom solimp="0.998 0.998 0.001" solref="0.001 1" density="100" friction="0.95 0.3 0.1" type="mesh" mesh="mug_5_normalized_collision_20._coll" group="3" rgba="0.8 0.8 0.8 0.0" />
        <geom solimp="0.998 0.998 0.001" solref="0.001 1" density="100" friction="0.95 0.3 0.1" type="mesh" mesh="mug_5_normalized_collision_24._coll" group="3" rgba="0.8 0.8 0.8 0.0" />
        <geom solimp="0.998 0.998 0.001" solref="0.001 1" density="100" friction="0.95 0.3 0.1" type="mesh" mesh="mug_5_normalized_collision_30._coll" group="3" rgba="0.8 0.8 0.8 0.0" />
        <geom solimp="0.998 0.998 0.001" solref="0.001 1" density="100" friction="0.95 0.3 0.1" type="mesh" mesh="mug_5_normalized_collision_18._coll" group="3" rgba="0.8 0.8 0.8 0.0" />
        <geom solimp="0.998 0.998 0.001" solref="0.001 1" density="100" friction="0.95 0.3 0.1" type="mesh" mesh="mug_5_normalized_collision_19._coll" group="3" rgba="0.8 0.8 0.8 0.0" />
        <geom solimp="0.998 0.998 0.001" solref="0.001 1" density="100" friction="0.95 0.3 0.1" type="mesh" mesh="mug_5_normalized_collision_31._coll" group="3" rgba="0.8 0.8 0.8 0.0" />
        <geom solimp="0.998 0.998 0.001" solref="0.001 1" density="100" friction="0.95 0.3 0.1" type="mesh" mesh="mug_5_normalized_collision_25._coll" group="3" rgba="0.8 0.8 0.8 0.0" />
        <geom solimp="0.998 0.998 0.001" solref="0.001 1" density="100" friction="0.95 0.3 0.1" type="mesh" mesh="mug_5_normalized_collision_27._coll" group="3" rgba="0.8 0.8 0.8 0.0" />
        <geom solimp="0.998 0.998 0.001" solref="0.001 1" density="100" friction="0.95 0.3 0.1" type="mesh" mesh="mug_5_normalized_collision_26._coll" group="3" rgba="0.8 0.8 0.8 0.0" />
        <geom solimp="0.998 0.998 0.001" solref="0.001 1" density="100" friction="0.95 0.3 0.1" type="mesh" mesh="mug_5_normalized_collision_9._coll" group="3" rgba="0.8 0.8 0.8 0.0" />
        <geom solimp="0.998 0.998 0.001" solref="0.001 1" density="100" friction="0.95 0.3 0.1" type="mesh" mesh="mug_5_normalized_collision_8._coll" group="3" rgba="0.8 0.8 0.8 0.0" />
        <geom solimp="0.998 0.998 0.001" solref="0.001 1" density="100" friction="0.95 0.3 0.1" type="mesh" mesh="mug_5_normalized_collision_6._coll" group="3" rgba="0.8 0.8 0.8 0.0" />
        <geom solimp="0.998 0.998 0.001" solref="0.001 1" density="100" friction="0.95 0.3 0.1" type="mesh" mesh="mug_5_normalized_collision_7._coll" group="3" rgba="0.8 0.8 0.8 0.0" />
        <geom solimp="0.998 0.998 0.001" solref="0.001 1" density="100" friction="0.95 0.3 0.1" type="mesh" mesh="mug_5_normalized_collision_5._coll" group="3" rgba="0.8 0.8 0.8 0.0" />
        <geom solimp="0.998 0.998 0.001" solref="0.001 1" density="100" friction="0.95 0.3 0.1" type="mesh" mesh="mug_5_normalized_collision_4._coll" group="3" rgba="0.8 0.8 0.8 0.0" />
        <geom solimp="0.998 0.998 0.001" solref="0.001 1" density="100" friction="0.95 0.3 0.1" type="mesh" mesh="mug_5_normalized_collision_0._coll" group="3" rgba="0.8 0.8 0.8 0.0" />
        <geom solimp="0.998 0.998 0.001" solref="0.001 1" density="100" friction="0.95 0.3 0.1" type="mesh" mesh="mug_5_normalized_collision_1._coll" group="3" rgba="0.8 0.8 0.8 0.0" />
        <geom solimp="0.998 0.998 0.001" solref="0.001 1" density="100" friction="0.95 0.3 0.1" type="mesh" mesh="mug_5_normalized_collision_3._coll" group="3" rgba="0.8 0.8 0.8 0.0" />
        <geom solimp="0.998 0.998 0.001" solref="0.001 1" density="100" friction="0.95 0.3 0.1" type="mesh" mesh="mug_5_normalized_collision_2._coll" group="3" rgba="0.8 0.8 0.8 0.0" />
        <geom solimp="0.998 0.998 0.001" solref="0.001 1" density="100" friction="0.95 0.3 0.1" type="mesh" mesh="mug_5_normalized_collision_17._coll" group="3" rgba="0.8 0.8 0.8 0.0" />
        <geom solimp="0.998 0.998 0.001" solref="0.001 1" density="100" friction="0.95 0.3 0.1" type="mesh" mesh="mug_5_normalized_collision_16._coll" group="3" rgba="0.8 0.8 0.8 0.0" />
        <geom solimp="0.998 0.998 0.001" solref="0.001 1" density="100" friction="0.95 0.3 0.1" type="mesh" mesh="mug_5_normalized_collision_28._coll" group="3" rgba="0.8 0.8 0.8 0.0" />
        <geom solimp="0.998 0.998 0.001" solref="0.001 1" density="100" friction="0.95 0.3 0.1" type="mesh" mesh="mug_5_normalized_collision_14._coll" group="3" rgba="0.8 0.8 0.8 0.0" />
        <geom solimp="0.998 0.998 0.001" solref="0.001 1" density="100" friction="0.95 0.3 0.1" type="mesh" mesh="mug_5_normalized_collision_15._coll" group="3" rgba="0.8 0.8 0.8 0.0" />
        <geom solimp="0.998 0.998 0.001" solref="0.001 1" density="100" friction="0.95 0.3 0.1" type="mesh" mesh="mug_5_normalized_collision_29._coll" group="3" rgba="0.8 0.8 0.8 0.0" />
        <geom solimp="0.998 0.998 0.001" solref="0.001 1" density="100" friction="0.95 0.3 0.1" type="mesh" mesh="mug_5_normalized_collision_11._coll" group="3" rgba="0.8 0.8 0.8 0.0" />
        <geom solimp="0.998 0.998 0.001" solref="0.001 1" density="100" friction="0.95 0.3 0.1" type="mesh" mesh="mug_5_normalized_collision_10._coll" group="3" rgba="0.8 0.8 0.8 0.0" />
        <geom solimp="0.998 0.998 0.001" solref="0.001 1" density="100" friction="0.95 0.3 0.1" type="mesh" mesh="mug_5_normalized_collision_12._coll" group="3" rgba="0.8 0.8 0.8 0.0" />
        <geom solimp="0.998 0.998 0.001" solref="0.001 1" density="100" friction="0.95 0.3 0.1" type="mesh" mesh="mug_5_normalized_collision_13._coll" group="3" rgba="0.8 0.8 0.8 0.0" />
      </body>
      <site rgba="0 0 0 0" size="0.005" pos="4.243902500000201e-05 7.88710249999995e-05 -0.0428075701" name="bottom_site_mug_5" />
      <site rgba="0 0 0 0" size="0.005" pos="4.243902500000201e-05 7.88710249999995e-05 0.042628894599999995" name="top_site_mug_5" />
      <site rgba="0 0 0 0" size="0.005" pos="0.04203482185 0.05653210019999999 -8.933774999999949e-05" name="horizontal_radius_site_mug_5" />
    </body><body name="body_obj_plate_11">
      <freejoint /><body name="object_plate_11">
        <geom solimp="0.998 0.998 0.001" solref="0.001 1" density="100" friction="0.95 0.3 0.1" type="mesh" mesh="plate_11_normalized_0_vis" conaffinity="0" contype="0" group="2" material="Material.387_plate_11" />
        <geom solimp="0.998 0.998 0.001" solref="0.001 1" density="100" friction="0.95 0.3 0.1" type="mesh" mesh="plate_11_normalized_collision_22._coll" group="3" rgba="0.8 0.8 0.8 0.0" />
        <geom solimp="0.998 0.998 0.001" solref="0.001 1" density="100" friction="0.95 0.3 0.1" type="mesh" mesh="plate_11_normalized_collision_23._coll" group="3" rgba="0.8 0.8 0.8 0.0" />
        <geom solimp="0.998 0.998 0.001" solref="0.001 1" density="100" friction="0.95 0.3 0.1" type="mesh" mesh="plate_11_normalized_collision_21._coll" group="3" rgba="0.8 0.8 0.8 0.0" />
        <geom solimp="0.998 0.998 0.001" solref="0.001 1" density="100" friction="0.95 0.3 0.1" type="mesh" mesh="plate_11_normalized_collision_20._coll" group="3" rgba="0.8 0.8 0.8 0.0" />
        <geom solimp="0.998 0.998 0.001" solref="0.001 1" density="100" friction="0.95 0.3 0.1" type="mesh" mesh="plate_11_normalized_collision_24._coll" group="3" rgba="0.8 0.8 0.8 0.0" />
        <geom solimp="0.998 0.998 0.001" solref="0.001 1" density="100" friction="0.95 0.3 0.1" type="mesh" mesh="plate_11_normalized_collision_30._coll" group="3" rgba="0.8 0.8 0.8 0.0" />
        <geom solimp="0.998 0.998 0.001" solref="0.001 1" density="100" friction="0.95 0.3 0.1" type="mesh" mesh="plate_11_normalized_collision_18._coll" group="3" rgba="0.8 0.8 0.8 0.0" />
        <geom solimp="0.998 0.998 0.001" solref="0.001 1" density="100" friction="0.95 0.3 0.1" type="mesh" mesh="plate_11_normalized_collision_19._coll" group="3" rgba="0.8 0.8 0.8 0.0" />
        <geom solimp="0.998 0.998 0.001" solref="0.001 1" density="100" friction="0.95 0.3 0.1" type="mesh" mesh="plate_11_normalized_collision_31._coll" group="3" rgba="0.8 0.8 0.8 0.0" />
        <geom solimp="0.998 0.998 0.001" solref="0.001 1" density="100" friction="0.95 0.3 0.1" type="mesh" mesh="plate_11_normalized_collision_25._coll" group="3" rgba="0.8 0.8 0.8 0.0" />
        <geom solimp="0.998 0.998 0.001" solref="0.001 1" density="100" friction="0.95 0.3 0.1" type="mesh" mesh="plate_11_normalized_collision_27._coll" group="3" rgba="0.8 0.8 0.8 0.0" />
        <geom solimp="0.998 0.998 0.001" solref="0.001 1" density="100" friction="0.95 0.3 0.1" type="mesh" mesh="plate_11_normalized_collision_26._coll" group="3" rgba="0.8 0.8 0.8 0.0" />
        <geom solimp="0.998 0.998 0.001" solref="0.001 1" density="100" friction="0.95 0.3 0.1" type="mesh" mesh="plate_11_normalized_collision_9._coll" group="3" rgba="0.8 0.8 0.8 0.0" />
        <geom solimp="0.998 0.998 0.001" solref="0.001 1" density="100" friction="0.95 0.3 0.1" type="mesh" mesh="plate_11_normalized_collision_8._coll" group="3" rgba="0.8 0.8 0.8 0.0" />
        <geom solimp="0.998 0.998 0.001" solref="0.001 1" density="100" friction="0.95 0.3 0.1" type="mesh" mesh="plate_11_normalized_collision_6._coll" group="3" rgba="0.8 0.8 0.8 0.0" />
        <geom solimp="0.998 0.998 0.001" solref="0.001 1" density="100" friction="0.95 0.3 0.1" type="mesh" mesh="plate_11_normalized_collision_7._coll" group="3" rgba="0.8 0.8 0.8 0.0" />
        <geom solimp="0.998 0.998 0.001" solref="0.001 1" density="100" friction="0.95 0.3 0.1" type="mesh" mesh="plate_11_normalized_collision_5._coll" group="3" rgba="0.8 0.8 0.8 0.0" />
        <geom solimp="0.998 0.998 0.001" solref="0.001 1" density="100" friction="0.95 0.3 0.1" type="mesh" mesh="plate_11_normalized_collision_4._coll" group="3" rgba="0.8 0.8 0.8 0.0" />
        <geom solimp="0.998 0.998 0.001" solref="0.001 1" density="100" friction="0.95 0.3 0.1" type="mesh" mesh="plate_11_normalized_collision_0._coll" group="3" rgba="0.8 0.8 0.8 0.0" />
        <geom solimp="0.998 0.998 0.001" solref="0.001 1" density="100" friction="0.95 0.3 0.1" type="mesh" mesh="plate_11_normalized_collision_1._coll" group="3" rgba="0.8 0.8 0.8 0.0" />
        <geom solimp="0.998 0.998 0.001" solref="0.001 1" density="100" friction="0.95 0.3 0.1" type="mesh" mesh="plate_11_normalized_collision_3._coll" group="3" rgba="0.8 0.8 0.8 0.0" />
        <geom solimp="0.998 0.998 0.001" solref="0.001 1" density="100" friction="0.95 0.3 0.1" type="mesh" mesh="plate_11_normalized_collision_2._coll" group="3" rgba="0.8 0.8 0.8 0.0" />
        <geom solimp="0.998 0.998 0.001" solref="0.001 1" density="100" friction="0.95 0.3 0.1" type="mesh" mesh="plate_11_normalized_collision_17._coll" group="3" rgba="0.8 0.8 0.8 0.0" />
        <geom solimp="0.998 0.998 0.001" solref="0.001 1" density="100" friction="0.95 0.3 0.1" type="mesh" mesh="plate_11_normalized_collision_16._coll" group="3" rgba="0.8 0.8 0.8 0.0" />
        <geom solimp="0.998 0.998 0.001" solref="0.001 1" density="100" friction="0.95 0.3 0.1" type="mesh" mesh="plate_11_normalized_collision_28._coll" group="3" rgba="0.8 0.8 0.8 0.0" />
        <geom solimp="0.998 0.998 0.001" solref="0.001 1" density="100" friction="0.95 0.3 0.1" type="mesh" mesh="plate_11_normalized_collision_14._coll" group="3" rgba="0.8 0.8 0.8 0.0" />
        <geom solimp="0.998 0.998 0.001" solref="0.001 1" density="100" friction="0.95 0.3 0.1" type="mesh" mesh="plate_11_normalized_collision_15._coll" group="3" rgba="0.8 0.8 0.8 0.0" />
        <geom solimp="0.998 0.998 0.001" solref="0.001 1" density="100" friction="0.95 0.3 0.1" type="mesh" mesh="plate_11_normalized_collision_29._coll" group="3" rgba="0.8 0.8 0.8 0.0" />
        <geom solimp="0.998 0.998 0.001" solref="0.001 1" density="100" friction="0.95 0.3 0.1" type="mesh" mesh="plate_11_normalized_collision_11._coll" group="3" rgba="0.8 0.8 0.8 0.0" />
        <geom solimp="0.998 0.998 0.001" solref="0.001 1" density="100" friction="0.95 0.3 0.1" type="mesh" mesh="plate_11_normalized_collision_10._coll" group="3" rgba="0.8 0.8 0.8 0.0" />
        <geom solimp="0.998 0.998 0.001" solref="0.001 1" density="100" friction="0.95 0.3 0.1" type="mesh" mesh="plate_11_normalized_collision_12._coll" group="3" rgba="0.8 0.8 0.8 0.0" />
        <geom solimp="0.998 0.998 0.001" solref="0.001 1" density="100" friction="0.95 0.3 0.1" type="mesh" mesh="plate_11_normalized_collision_13._coll" group="3" rgba="0.8 0.8 0.8 0.0" />
      </body>
      <site rgba="0 0 0 0" size="0.005" pos="1.8500000041610231e-09 1.8499999990262416e-09 -0.00589834945" name="bottom_site_plate_11" />
      <site rgba="0 0 0 0" size="0.005" pos="1.8500000041610231e-09 1.8499999990262416e-09 0.005789232750000001" name="top_site_plate_11" />
      <site rgba="0 0 0 0" size="0.005" pos="0.0912271556 0.09122715005 -5.45583499999998e-05" name="horizontal_radius_site_plate_11" />
    </body></worldbody>

  <tendon>
    <fixed name="split">
      <joint joint="finger_joint1" coef="0.5" />
      <joint joint="finger_joint2" coef="0.5" />
    </fixed>
  </tendon>

  <equality>
    <joint joint1="finger_joint1" joint2="finger_joint2" solimp="0.95 0.99 0.001" solref="0.005 1" />
  </equality>

  <actuator>
    <general class="panda" name="actuator1" joint="joint1" gainprm="4500" biasprm="0 -4500 -450" />
    <general class="panda" name="actuator2" joint="joint2" gainprm="4500" biasprm="0 -4500 -450" ctrlrange="-1.7628 1.7628" />
    <general class="panda" name="actuator3" joint="joint3" gainprm="3500" biasprm="0 -3500 -350" />
    <general class="panda" name="actuator4" joint="joint4" gainprm="3500" biasprm="0 -3500 -350" ctrlrange="-3.0718 -0.0698" />
    <general class="panda" name="actuator5" joint="joint5" gainprm="2000" biasprm="0 -2000 -200" forcerange="-12 12" />
    <general class="panda" name="actuator6" joint="joint6" gainprm="2000" biasprm="0 -2000 -200" forcerange="-12 12" ctrlrange="-0.0175 3.7525" />
    <general class="panda" name="actuator7" joint="joint7" gainprm="2000" biasprm="0 -2000 -200" forcerange="-12 12" />
    
    <general class="panda" name="actuator8" tendon="split" forcerange="-100 100" ctrlrange="0 255" gainprm="0.01568627451 0 0" biasprm="0 -100 -10" />
  </actuator>

  <contact>
    <exclude body1="link0" body2="link1" />
  </contact>
</mujoco>